Workbook
Name Die_Vergütung_aller_Mitarbeiter_erfolgt_derzeit_nach_dem_Tarif: Dateneingabe!$A$100
Name Marco_Besse: #REF!
Name Tarifvertrag: Dateneingabe!$N$3:$N$12

Sheet Dateneingabe
A1: A. Angabe der Grunddaten
A3: Name und Anschrift des Trägers | E3: Name und Anschrift der Einrichtung
A4: Pflegedienst MORO GmbH | E4: Pflegedienst MORO GmbH
A5: Provinzialstr. 82 | E5: Provinzialstr. 82
A6: 44388 | C6: Dortmund | E6: 44388 | F6: Dortmund
C8: IK-Nummer | D8: 460 502 542 | E8: Kreis / kreisfreie Stadt: | F8: Dortmund
A10: Mitglied im Verband: | C10: bpa
A13: Verhandlungsart | C13: Pauschalverhandlung
E15: von | F15: bis
A16: Erhebungszeitraum (letztes abgeschlossenes Geschäftsjahr): | E16: 45292 | F16: 45657
A17: Vereinbarungszeitraum: | E17: 46023 | F17: 46387
C19: Punktwert* | D19: LK 15 | E19: LK 15a
A20: letzte Vereinbarung | C20: 0.06076 | D20: 5.59 | E20: 6.97
A21: Forderung | C21: 0.06289 | D21: 5.79 | E21: 7.21
A22: *ohne Ausbildungszuschlag gem. PflBG | D22: Begründung für die Forderung siehe ggf. Anlage 1
A24: B. Angabe der Leistungen im Bereich SGB XI | G24: =D8 -> 460 502 542
A25: Durchschnittlich versorgte Pflegebedürftige im Erhebungszeitraum
A26: (durchschnittliche Anzahl der Kunden p.a.)
A27: (nur die Kunden zählen anteilig, die mindestens an einem Tag in einem Kalendermonat Pflegesachleistungen (ohne § 37 Abs. 3) erhalten haben)
A29: Pflegegrade
A30: 1 | C30: 2 | D30: 3 | E30: 4 | F30: 5 | G30: Gesamt
A31: 5 | C31: 40 | D31: 12 | E31: 10 | F31: 3 | G31: =SUM(A31:F31) -> 70
A33: Leistungen | F33: Erhebungszeitraum
A34: Nr. | B34: Komplex | F34: Anzahl
A35: P01 | B35: Ganzwaschung | F35: 1223
A36: P02 | B36: Teilwaschung | F36: 1363
A37: P03 | B37: Ausscheidungen | F37: 73
A38: P04 | B38: selbständige Nahrungsaufnahme | F38: 751
A39: P05 | B39: Hilfe bei der Nahrungsaufnahme | F39: 0
A40: P06 | B40: Sondenernährung | F40: 314
A41: P07 | B41: Lagern / Betten | F41: 0
A42: P08 | B42: Mobilisation | F42: 0
A43: P09 | B43: Behördengänge und Arztbesuche | F43: 0
A44: P10 | B44: Beheizen des Wohnbereichs | F44: 0
A45: P11 | B45: Einkaufen | F45: 116
A46: P12 | B46: Zubereiten von warmen Mahlzeiten | F46: 0
... A69: P33 | B69: Hauswirtschaftliche Versorgung** | F69: 0
A71: ** Anzahl der Minuten im Jahr
A74: C. Angabe zur Personalstruktur | F74: IK-Nummer | G74: =G24 -> 460 502 542
A75: (Anzahl der Beschäftigten ausschließlich im SGB XI Bereich, umgerechnet in Vollzeitstellen)
...

Sheet Budgetsteigerung
B1: Ermittlung der Budgetsteigerung
L2: sollten später mit weisser Schrfit auf weissem Untergrund "unsichtbar" gemacht werden
B3: bisherige gültige Vereinbarung:
B4: Punktwert: | C4: =Dateneingabe!C20 -> 0.06076 | D4: ohne Refinanzierungszuschlag
B5: LK 15: | C5: =Dateneingabe!D20 -> 5.59
B6: LK 15a: | C6: =Dateneingabe!E20 -> 6.97
O10: Umsatzvolumen | Q10: Einzelpreis | R10: Umsatzvolumen | T10: Einzelpreis | U10: Umsatzvolumen | W10: Einzelpreis | X10: Umsatzvolumen
B11: in der Zeit vom: | C11: =Dateneingabe!E16 -> 45292 | D11: bis zum: | E11: =Dateneingabe!F16 -> 45657 | G11: eintragen | H11: Einzelpreis ohne Refinanzierung | M11: Punktevolumen | O11: bisherig | Q11: lineare Steigerung | T11: Forderung | W11: individuelle Kalkulation
B12: 1 | C12: Ganzwaschung | F12: 426 | G12: =Dateneingabe!F35 -> 1223 | H12: =ROUND(C$4*F12,2) -> 25.88 | M12: =F12*G12 -> 520998 | O12: =ROUND(G12*H12,2) -> 31651.24 | Q12: =IF($F$55="",0,ROUND($F$55*F12,2)) -> 26.79 | R12: =Q12*G12 -> 32764.17 | T12: =ROUND($H$55*F12,2) -> 26.79 | U12: =T12*G12 -> 32764.17 | W12: =ROUND($L$55*F12,2) -> 0 | X12: =W12*G12 -> 0
B13: 2 | C13: Teilwaschung | F13: 228 | G13: =Dateneingabe!F36 -> 1363 | H13: =ROUND(C$4*F13,2) -> 13.85 | M13: =F13*G13 -> 310764 | O13: =ROUND(G13*H13,2) -> 18877.55 | Q13: =IF($F$55="",0,ROUND($F$55*F13,2)) -> 14.34 | R13: =Q13*G13 -> 19545.42 | T13: =ROUND($H$55*F13,2) -> 14.34 | U13: =T13*G13 -> 19545.42 | W13: =ROUND($L$55*F13,2) -> 0 | X13: =W13*G13 -> 0
B14: 3 | C14: Ausscheidungen | F14: 104 | G14: =Dateneingabe!F37 -> 73 | H14: =ROUND(C$4*F14,2) -> 6.32 | M14: =F14*G14 -> 7592 | O14: =ROUND(G14*H14,2) -> 461.36 | Q14: =IF($F$55="",0,ROUND($F$55*F14,2)) -> 6.54 | R14: =Q14*G14 -> 477.42 | T14: =ROUND($H$55*F14,2) -> 6.54 | U14: =T14*G14 -> 477.42 | W14: =ROUND($L$55*F14,2) -> 0 | X14: =W14*G14 -> 0
B15: 4 | C15: selbst. Nahrungsaufn. | F15: 104 | G15: =Dateneingabe!F38 -> 751 | H15: =ROUND(C$4*F15,2) -> 6.32 | M15: =F15*G15 -> 78104 | O15: =ROUND(G15*H15,2) -> 4746.32 | Q15: =IF($F$55="",0,ROUND($F$55*F15,2)) -> 6.54 | R15: =Q15*G15 -> 4911.54 | T15: =ROUND($H$55*F15,2) -> 6.54 | U15: =T15*G15 -> 4911.54 | W15: =ROUND($L$55*F15,2) -> 0 | X15: =W15*G15 -> 0
B16: 5 | C16: Hilfe Nahrungsaufn. | F16: 260 | G16: =Dateneingabe!F39 -> 0 | H16: =ROUND(C$4*F16,2) -> 15.8 | M16: =F16*G16 -> 0 | O16: =ROUND(G16*H16,2) -> 0 | Q16: =IF($F$55="",0,ROUND($F$55*F16,2)) -> 16.35 | R16: =Q16*G16 -> 0 | T16: =ROUND($H$55*F16,2) -> 16.35 | U16: =T16*G16 -> 0 | W16: =ROUND($L$55*F16,2) -> 0 | X16: =W16*G16 -> 0
B17: 6 | C17: Sondenern. (PEG) | F17: 104 | G17: =Dateneingabe!F40 -> 314 | H17: =ROUND(C$4*F17,2) -> 6.32 | M17: =F17*G17 -> 32656 | O17: =ROUND(G17*H17,2) -> 1984.48 | Q17: =IF($F$55="",0,ROUND($F$55*F17,2)) -> 6.54 | R17: =Q17*G17 -> 2053.56 | T17: =ROUND($H$55*F17,2) -> 6.54 | U17: =T17*G17 -> 2053.56 | W17: =ROUND($L$55*F17,2) -> 0 | X17: =W17*G17 -> 0
B18: 7 | C18: Lagern / Betten | F18: 104 | G18: =Dateneingabe!F41 -> 0 | H18: =ROUND(C$4*F18,2) -> 6.32 | M18: =F18*G18 -> 0 | O18: =ROUND(G18*H18,2) -> 0 | Q18: =IF($F$55="",0,ROUND($F$55*F18,2)) -> 6.54 | R18: =Q18*G18 -> 0 | T18: =ROUND($H$55*F18,2) -> 6.54 | U18: =T18*G18 -> 0 | W18: =ROUND($L$55*F18,2) -> 0 | X18: =W18*G18 -> 0
B19: 8 | C19: Mobilisation | F19: 187 | G19: =Dateneingabe!F42 -> 0 | H19: =ROUND(C$4*F19,2) -> 11.36 | M19: =F19*G19 -> 0 | O19: =ROUND(G19*H19,2) -> 0 | Q19: =IF($F$55="",0,ROUND($F$55*F19,2)) -> 11.76 | R19: =Q19*G19 -> 0 | T19: =ROUND($H$55*F19,2) -> 11.76 | U19: =T19*G19 -> 0 | W19: =ROUND($L$55*F19,2) -> 0 | X19: =W19*G19 -> 0
B20: 9 | C20: Behördeng. Arztbes. | F20: 360 | G20: =Dateneingabe!F43 -> 0 | H20: =ROUND(C$4*F20,2) -> 21.87 | M20: =F20*G20 -> 0 | O20: =ROUND(G20*H20,2) -> 0 | Q20: =IF($F$55="",0,ROUND($F$55*F20,2)) -> 22.64 | R20: =Q20*G20 -> 0 | T20: =ROUND($H$55*F20,2) -> 22.64 | U20: =T20*G20 -> 0 | W20: =ROUND($L$55*F20,2) -> 0 | X20: =W20*G20 -> 0
B21: 10 | C21: Beheizen | F21: 60 | G21: =Dateneingabe!F44 -> 0 | H21: =ROUND(C$4*F21,2) -> 3.65 | M21: =F21*G21 -> 0 | O21: =ROUND(G21*H21,2) -> 0 | Q21: =IF($F$55="",0,ROUND($F$55*F21,2)) -> 3.77 | R21: =Q21*G21 -> 0 | T21: =ROUND($H$55*F21,2) -> 3.77 | U21: =T21*G21 -> 0 | W21: =ROUND($L$55*F21,2) -> 0 | X21: =W21*G21 -> 0
B22: 11 | C22: Einkaufen | F22: 150 | G22: =Dateneingabe!F45 -> 116 | H22: =ROUND(C$4*F22,2) -> 9.11 | M22: =F22*G22 -> 17400 | O22: =ROUND(G22*H22,2) -> 1056.76 | Q22: =IF($F$55="",0,ROUND($F$55*F22,2)) -> 9.43 | R22: =Q22*G22 -> 1093.88 | T22: =ROUND($H$55*F22,2) -> 9.43 | U22: =T22*G22 -> 1093.88 | W22: =ROUND($L$55*F22,2) -> 0 | X22: =W22*G22 -> 0
B23: 12 | C23: Zubereitung warme Sp. | F23: 150 | G23: =Dateneingabe!F46 -> 0 | H23: =ROUND(C$4*F23,2) -> 9.11 | M23: =F23*G23 -> 0 | O23: =ROUND(G23*H23,2) -> 0 | Q23: =IF($F$55="",0,ROUND($F$55*F23,2)) -> 9.43 | R23: =Q23*G23 -> 0 | T23: =ROUND($H$55*F23,2) -> 9.43 | U23: =T23*G23 -> 0 | W23: =ROUND($L$55*F23,2) -> 0 | X23: =W23*G23 -> 0
... B25: 14 | C25: Wäsche | F25: 360 | G25: =Dateneingabe!F48 -> 32 | H25: =ROUND(C$4*F25,2) -> 21.87 | M25: =F25*G25 -> 11520 | O25: =ROUND(G25*H25,2) -> 699.84 | Q25: =IF($F$55="",0,ROUND($F$55*F25,2)) -> 22.64 | R25: =Q25*G25 -> 724.48 | T25: =ROUND($H$55*F25,2) -> 22.64 | U25: =T25*G25 -> 724.48 | W25: =ROUND($L$55*F25,2) -> 0 | X25: =W25*G25 -> 0
B26: 15 | C26: Hausbes.-pauschale | G26: =Dateneingabe!F49 -> 7159 | H26: =C5 -> 5.59 | N26: =IF(C4=0,0,ROUND(C5/C4,0)*G26) -> 658628 | O26: =G26*H26 -> 40018.81 | Q26: =F56 -> 5.79 | R26: =Q26*G26 -> 41450.61 | T26: =H56 -> 5.79 | U26: =T26*G26 -> 41450.61 | W26: =L56 -> 0 | X26: =W26*G26 -> 0
B27: 15 a | C27: erhöhte Besuchsp. | G27: =Dateneingabe!F50 -> 1586 | H27: =C6 -> 6.97 | N27: =IF(C4=0,0,ROUND(C6/C4,0)*G27) -> 182390 | O27: =G27*H27 -> 11054.42 | Q27: =F57 -> 7.21 | R27: =Q27*G27 -> 11435.06 | T27: =H57 -> 7.21 | U27: =T27*G27 -> 11435.06 | W27: =L57 -> 0 | X27: =W27*G27 -> 0
B28: 16 | C28: Erstgespräch | F28: 1600 | G28: =Dateneingabe!F51 -> 0 | H28: =ROUND(C$4*F28,2) -> 97.22 | M28: =F28*G28 -> 0 | O28: =G28*H28 -> 0 | Q28: =IF($F$55="",0,ROUND($F$55*F28,2)) -> 100.62 | R28: =Q28*G28 -> 0 | T28: =ROUND($H$55*F28,2) -> 100.62 | U28: =T28*G28 -> 0 | W28: =ROUND($L$55*F28,2) -> 0 | X28: =W28*G28 -> 0
B29: 16 a | C29: Folgegespräch | F29: 900 | G29: =Dateneingabe!F52 -> 0 | H29: =ROUND(C$4*F29,2) -> 54.68 | M29: =F29*G29 -> 0 | O29: =G29*H29 -> 0 | Q29: =IF($F$55="",0,ROUND($F$55*F29,2)) -> 56.6 | R29: =Q29*G29 -> 0 | T29: =ROUND($H$55*F29,2) -> 56.6 | U29: =T29*G29 -> 0 | W29: =ROUND($L$55*F29,2) -> 0 | X29: =W29*G29 -> 0
B30: 17 | C30: Beratungsbesuch | F30: 1350 | G30: =Dateneingabe!F53 -> 343 | H30: =ROUND(C$4*F30,2) -> 82.03 | M30: =F30*G30 -> 463050 | O30: =G30*H30 -> 28136.29 | Q30: =IF($F$55="",0,ROUND($F$55*F30,2)) -> 84.9 | R30: =Q30*G30 -> 29120.7 | T30: =ROUND($H$55*F30,2) -> 84.9 | U30: =T30*G30 -> 29120.7 | W30: =ROUND($L$55*F30,2) -> 0 | X30: =W30*G30 -> 0
B31: 18 | C31: Große Grundpflege 1 | F31: 633 | G31: =Dateneingabe!F54 -> 15 | H31: =ROUND(C$4*F31,2) -> 38.46 | M31: =F31*G31 -> 9495 | O31: =G31*H31 -> 576.9 | Q31: =IF($F$55="",0,ROUND($F$55*F31,2)) -> 39.81 | R31: =Q31*G31 -> 597.15 | T31: =ROUND($H$55*F31,2) -> 39.81 | U31: =T31*G31 -> 597.15 | W31: =ROUND($L$55*F31,2) -> 0 | X31: =W31*G31 -> 0
B32: 19 | C32: Große Grundpflege 2 | F32: 467 | G32: =Dateneingabe!F55 -> 827 | H32: =ROUND(C$4*F32,2) -> 28.37 | M32: =F32*G32 -> 386209 | O32: =G32*H32 -> 23461.99 | Q32: =IF($F$55="",0,ROUND($F$55*F32,2)) -> 29.37 | R32: =Q32*G32 -> 24288.99 | T32: =ROUND($H$55*F32,2) -> 29.37 | U32: =T32*G32 -> 24288.99 | W32: =ROUND($L$55*F32,2) -> 0 | X32: =W32*G32 -> 0
B33: 20 | C33: Kleine Grundpflege 1 | F33: 467 | G33: =Dateneingabe!F56 -> 0 | H33: =ROUND(C$4*F33,2) -> 28.37 | M33: =F33*G33 -> 0 | O33: =G33*H33 -> 0 | Q33: =IF($F$55="",0,ROUND($F$55*F33,2)) -> 29.37 | R33: =Q33*G33 -> 0 | T33: =ROUND($H$55*F33,2) -> 29.37 | U33: =T33*G33 -> 0 | W33: =ROUND($L$55*F33,2) -> 0 | X33: =W33*G33 -> 0
B34: 21 | C34: Kleine Grundpflege 2 | F34: 301 | G34: =Dateneingabe!F57 -> 679 | H34: =ROUND(C$4*F34,2) -> 18.29 | M34: =F34*G34 -> 204379 | O34: =G34*H34 -> 12418.91 | Q34: =IF($F$55="",0,ROUND($F$55*F34,2)) -> 18.93 | R34: =Q34*G34 -> 12853.47 | T34: =ROUND($H$55*F34,2) -> 18.93 | U34: =T34*G34 -> 12853.47 | W34: =ROUND($L$55*F34,2) -> 0 | X34: =W34*G34 -> 0
B35: 22 | C35: Große hausw. Vers. | F35: 760 | G35: =Dateneingabe!F58 -> 109 | H35: =ROUND(C$4*F35,2) -> 46.18 | M35: =F35*G35 -> 82840 | O35: =G35*H35 -> 5033.62 | Q35: =IF($F$55="",0,ROUND($F$55*F35,2)) -> 47.8 | R35: =Q35*G35 -> 5210.2 | T35: =ROUND($H$55*F35,2) -> 47.8 | U35: =T35*G35 -> 5210.2 | W35: =ROUND($L$55*F35,2) -> 0 | X35: =W35*G35 -> 0
B36: 23 | C36: Große Grundpflege 3 | F36: 540 | G36: =Dateneingabe!F59 -> 781 | H36: =ROUND(C$4*F36,2) -> 32.81 | M36: =F36*G36 -> 421740 | O36: =G36*H36 -> 25624.61 | Q36: =IF($F$55="",0,ROUND($F$55*F36,2)) -> 33.96 | R36: =Q36*G36 -> 26522.76 | T36: =ROUND($H$55*F36,2) -> 33.96 | U36: =T36*G36 -> 26522.76 | W36: =ROUND($L$55*F36,2) -> 0 | X36: =W36*G36 -> 0
B37: 24 | C37: Große Grundpflege 4 | F37: 768 | G37: =Dateneingabe!F60 -> 0 | H37: =ROUND(C$4*F37,2) -> 46.66 | M37: =F37*G37 -> 0 | O37: =G37*H37 -> 0 | Q37: =IF($F$55="",0,ROUND($F$55*F37,2)) -> 48.3 | R37: =Q37*G37 -> 0 | T37: =ROUND($H$55*F37,2) -> 48.3 | U37: =T37*G37 -> 0 | W37: =ROUND($L$55*F37,2) -> 0 | X37: =W37*G37 -> 0
B38: 25 | C38: Kleine Grundpflege 3 | F38: 363 | G38: =Dateneingabe!F61 -> 1445 | H38: =ROUND(C$4*F38,2) -> 22.06 | M38: =F38*G38 -> 524535 | O38: =G38*H38 -> 31876.7 | Q38: =IF($F$55="",0,ROUND($F$55*F38,2)) -> 22.83 | R38: =Q38*G38 -> 32989.35 | T38: =ROUND($H$55*F38,2) -> 22.83 | U38: =T38*G38 -> 32989.35 | W38: =ROUND($L$55*F38,2) -> 0 | X38: =W38*G38 -> 0
B39: 26 | C39: Kleine Grundpflege 4 | F39: 602 | G39: =Dateneingabe!F62 -> 0 | H39: =ROUND(C$4*F39,2) -> 36.58 | M39: =F39*G39 -> 0 | O39: =G39*H39 -> 0 | Q39: =IF($F$55="",0,ROUND($F$55*F39,2)) -> 37.86 | R39: =Q39*G39 -> 0 | T39: =ROUND($H$55*F39,2) -> 37.86 | U39: =T39*G39 -> 0 | W39: =ROUND($L$55*F39,2) -> 0 | X39: =W39*G39 -> 0
B40: 27 | C40: Kleine pfleg. Hilfest.1 | F40: 104 | G40: =Dateneingabe!F63 -> 23 | H40: =ROUND(C$4*F40,2) -> 6.32 | M40: =F40*G40 -> 2392 | O40: =G40*H40 -> 145.36 | Q40: =IF($F$55="",0,ROUND($F$55*F40,2)) -> 6.54 | R40: =Q40*G40 -> 150.42 | T40: =ROUND($H$55*F40,2) -> 6.54 | U40: =T40*G40 -> 150.42 | W40: =ROUND($L$55*F40,2) -> 0 | X40: =W40*G40 -> 0
B41: 28 | C41: Kleine pfleg. Hilfest. 2 | F41: 104 | G41: =Dateneingabe!F64 -> 475 | H41: =ROUND(C$4*F41,2) -> 6.32 | M41: =F41*G41 -> 49400 | O41: =G41*H41 -> 3002 | Q41: =IF($F$55="",0,ROUND($F$55*F41,2)) -> 6.54 | R41: =Q41*G41 -> 3106.5 | T41: =ROUND($H$55*F41,2) -> 6.54 | U41: =T41*G41 -> 3106.5 | W41: =ROUND($L$55*F41,2) -> 0 | X41: =W41*G41 -> 0
... B43: 30 | C43: Kleine pfleg. Hilfest. 4 | F43: 80 | G43: =Dateneingabe!F66 -> 69 | H43: =ROUND(C$4*F43,2) -> 4.86 | M43: =F43*G43 -> 5520 | O43: =G43*H43 -> 335.34 | Q43: =IF($F$55="",0,ROUND($F$55*F43,2)) -> 5.03 | R43: =Q43*G43 -> 347.07 | T43: =ROUND($H$55*F43,2) -> 5.03 | U43: =T43*G43 -> 347.07 | W43: =ROUND($L$55*F43,2) -> 0 | X43: =W43*G43 -> 0
B44: 31 | C44: Pflegerische Betreuung* | F44: 625 | G44: =Dateneingabe!F67 -> 0 | H44: =ROUND((C4)*F44/60,2) -> 0.63 | I44: (Minutenpreis) | M44: =(ROUND(G44/60,2)*F44) -> 0 | O44: =G44*H44 -> 0 | Q44: =IF($F$55="",0,ROUND($F$55*F44/60,2)) -> 0.66 | R44: =Q44*G44 -> 0 | T44: =ROUND($H$55*F44/60,2) -> 0.66 | U44: =T44*G44 -> 0 | W44: =ROUND($L$55*F44/60,2) -> 0 | X44: =W44*G44 -> 0
B45: 32 | C45: Hilfe bei der Sicherstellung der selbstverantw. Haushaltsführ.* | F45: 625 | G45: =Dateneingabe!F68 -> 0 | H45: =ROUND((C4)*F45/60,2) -> 0.63 | I45: (Minutenpreis) | M45: =(ROUND(G45/60,2)*F45) -> 0 | O45: =G45*H45 -> 0 | Q45: =IF($F$55="",0,ROUND($F$55*F45/60,2)) -> 0.66 | R45: =Q45*G45 -> 0 | T45: =ROUND($H$55*F45/60,2) -> 0.66 | U45: =T45*G45 -> 0 | W45: =ROUND($L$55*F45/60,2) -> 0 | X45: =W45*G45 -> 0
...

Sheet DropDown
A1: Kreise | B1: Inflationsausgleichsprämie | E1: Tarifverträge | G1: Tarif | I1: Verbände | K1: Eingruppierung | L1: Erfahrungsstufe | M1: Qualifikation | O1: Verhandlungsart | R1: Arbeitszeit | T1: Anlehner | AB1: Anwender | AJ1: RüE | AR1: Basisbereinigung | BA1: Basisbereinigung
A2: Aachen | B2: mit Inflationsausgleichsprämie | E2: AVR Bayern | G2: Tarifanwender | I2: kein Mitglied | J2: 1 | K2: 0 | L2: 0 | M2: angelernte Hilfskräfte | O2: Einzelverhandlung | R2: 30 | T2: Tarif | U2: Art | V2: Laufzeitbeginn | W2: Laufzeitende | X2: PW | Y2: Lk15 | Z2: LK15a | AB2: Tarif | AC2: Art | AD2: Laufzeitbeginn | AE2: Laufzeitende | AF2: PW | AG2: Lk15 | AH2: LK15a | AJ2: Tarif | AK2: Art | AL2: Laufzeitbeginn | AM2: Laufzeitende | AN2: PW | AO2: Lk15 | AP2: LK15a | AR2: Tarif | AS2: Art | AT2: Laufzeitbeginn | AU2: Laufzeitende | AV2: PW | AW2: Lk15 | AX2: LK15a | AY2: % | BA2: Tarif | BB2: Art | BC2: Laufzeitbeginn | BD2: Laufzeitende | BE2: PW | BF2: Lk15 | BG2: LK15a
A3: Bielefeld | B3: ohne Inflationsausgleichsprämie | E3: AVR Caritas | G3: Tarifanlehner | I3: ABVP | J3: 1 | K3: 1 | L3: 1 | M3: Betreuungskräfte | O3: Pauschalverhandlung | R3: 30.5 | T3: AVR Bayern | U3: Anlehner | V3: 45778 | W3: 46022 | X3: 0.06592 | Y3: 6.06 | Z3: 7.56 | AB3: AVR Bayern | AC3: Anwender | AD3: 45778 | AE3: 31.12.2025 | AF3: 0.06822 | AG3: 6.28 | AH3: 7.82 | AJ3: regional übliches Entgelt | AL3: 46023 | AM3: 46387 | AN3: 0.06289 | AO3: 5.79 | AP3: 7.21 | AR3: AVR Bayern | AS3: Anlehner | AT3: 46023 | AV3: 0.0633 | AW3: 5.82 | AX3: 7.26 | BA3: AVR Bayern | BB3: Anwender | BC3: 46023 | BE3: 0.06551 | BF3: 6.03 | BG3: 7.51
A4: Bochum | E4: AVR DD (Diakonie) | G4: regional übliches Entgelt | I4: AWO | J4: 2 | K4: 2 | L4: 2 | M4: BFD und FSJ | R4: 31 | T4: AVR Caritas | U4: Anlehner | V4: 45870 | W4: 46053 | X4: 0.06428 | Y4: 5.91 | Z4: 7.37 | AB4: AVR Caritas | AC4: Anwender | AD4: 45870 | AE4: 46053 | AF4: 0.06667 | AG4: 6.14 | AH4: 7.65 | AR4: AVR Caritas | AS4: Anlehner | AT4: 46054 | AV4: 0.06341 | AW4: 5.83 | AX4: 7.27 | BA4: AVR Caritas | BB4: Anwender | BC4: 46054 | BE4: 0.06577 | BF4: 6.05 | BG4: 7.54
A5: Bonn | E5: AVR Johanniter (DWBO) | I5: bad e.V. | J5: 1 | K5: 3 | L5: 3 | M5: Geschäftsführung | R5: 31.5 | T5: AVR DD (Diakonie) | U5: Anlehner | V5: 45778 | W5: 46142 | X5: 0.06359 | Y5: 5.85 | Z5: 7.29 | AB5: AVR DD (Diakonie) | AC5: Anwender | AD5: 45778 | AE5: 46142 | AF5: 0.06608 | AG5: 6.08 | AH5: 7.58 | AR5: AVR DD (Diakonie) | AS5: Anlehner | AT5: 46143 | AV5: 0.06319 | AW5: 5.81 | AX5: 7.25 | BA5: AVR DD (Diakonie) | BB5: Anwender | BC5: 46143 | BE5: 0.06565 | BF5: 6.04 | BG5: 7.53
A6: Borken | E6: BAT-KF | I6: bpa | J6: 1 | K6: 4 | L6: 4 | M6: Leitung | R6: 32 | T6: AVR Johanniter (DWBO) | U6: Anlehner | V6: 45870 | W6: 46022 | X6: 0.06165 | Y6: 5.68 | Z6: 7.1 | AB6: AVR Johanniter (DWBO) | AC6: Anwender | AD6: 45870 | AE6: 31.12.2025 | AF6: 0.06435 | AG6: 5.93 | AH6: 7.38 | AR6: AVR Johanniter (DWBO) | AS6: Anlehner | AT6: 46023 | AV6: 0.05985 | AW6: 5.52 | AX6: 6.89 | BA6: AVR Johanniter (DWBO) | BB6: Anwender | BC6: 46023 | BE6: 0.06216 | BF6: 5.72 | BG6: 7.13
A7: Bottrop | E7: DRK RT | I7: DBfK | J7: 1 | K7: 5 | L7: 5 | M7: Pflegefachkräfte (staatlich examiniert) excl. Frei-stellungsanteil PDL | R7: 32.5 | T7: BAT-KF | U7: Anlehner | V7: 45870 | W7: 46142 | X7: 0.06399 | Y7: 5.89 | Z7: 7.34 | AB7: BAT-KF | AC7: Anwender | AD7: 45870 | AE7: 46142 | AF7: 0.06713 | AG7: 6.18 | AH7: 7.7 | AR7: BAT-KF | AS7: Anlehner | AT7: 46143 | AV7: 0.06341 | AW7: 5.83 | AX7: 7.27 | BA7: BAT-KF | BB7: Anwender | BC7: 46143 | BE7: 0.06577 | BF7: 6.05 | BG7: 7.54
A8: Coesfeld | E8: regional übliches Entgelt | I8: DCV | J8: 2 | K8: 6 | L8: 6 | M8: Pflegehilfskräfte (1-jährig) | R8: 33 | T8: DRK RT | U8: Anlehner | V8: 45992 | W8: 46295 | X8: 0.06411 | Y8: 5.9 | Z8: 7.35 | AB8: DRK RT | AC8: Anlehner | AD8: 45992 | AE8: 46295 | AF8: 0.06476 | AG8: 5.96 | AH8: 7.43 | AR8: DRK RT | AS8: Anlehner | AT8: 46296 | AV8: 0.06363 | AW8: 5.86 | AX8: 7.3 | BA8: DRK RT | BB8: Anlehner | BC8: 46296 | BE8: 0.06363 | BF8: 5.86 | BG8: 7.3
A9: Dortmund | E9: TVöD | I9: Der Paritätische | J9: 2 | K9: 7 | L9: 7 | M9: Sonstige | R9: 33.5 | T9: HT Maternus | U9: Anlehner | V9: 01.01.2025 | W9: 31.12.2025 | AB9: HT Maternus | AC9: Anwender | AD9: 01.01.2025 | AE9: 31.12.2025 | AR9: HT Maternus | AS9: Anlehner | BA9: HT Maternus | BB9: Anwender
A10: Duisburg | E10: VPD | I10: Diakonie | J10: 2 | K10: 8 | L10: 8 | M10: Verwaltung | R10: 34 | T10: HT Opseo | U10: Anlehner | V10: 01.01.2025 | W10: 31.12.2025 | AB10: HT Opseo | AC10: Anwender | AD10: 01.01.2025 | AE10: 31.12.2025 | AR10: HT Opseo | AS10: Anlehner | BA10: HT Opseo | BB10: Anwender
A11: Düren | E11: PTG | I11: DRK | J11: 2 | K11: 9 | L11: 9 | R11: 34.5 | T11: TV AWO | U11: Anlehner | V11: 45931 | W11: 46022 | X11: 0.06544 | Y11: 6.02 | Z11: 7.5 | AB11: TV AWO | AC11: Anwender | AD11: 45931 | AE11: 46022 | AF11: 0.06579 | AG11: 6.06 | AH11: 7.55 | AR11: TV AWO | AS11: Anlehner | AT11: 46023 | AV11: 0.06386 | AW11: 5.88 | AX11: 7.32 | BA11: TV AWO | BB11: Anwender | BC11: 46023 | BE11: 0.0642 | BF11: 5.91 | BG11: 7.36
A12: Düsseldorf | E12: TV AWO | I12: LfK | J12: 1 | K12: 10 | L12: 10 | R12: 35 | T12: PTG | U12: Anlehner | V12: 45870 | W12: 31.12.2025 | X12: 0.0618 | Y12: 5.69 | Z12: 7.09 | AB12: PTG | AC12: Anwender | AD12: 45870 | AE12: 31.12.2025 | AF12: 0.0618 | AG12: 5.69 | AH12: 7.09 | AR12: PTG | AS12: Anlehner | AT12: 46023 | AV12: 0.0612 | AW12: 5.63 | AX12: 7.02 | BA12: PTG | BB12: Anwender | BC12: 46023 | BE12: 0.0612 | BF12: 5.63 | BG12: 7.02
A13: Ennepe-Ruhr-Kreis | E13: HT Maternus | I13: VDAB | J13: 1 | K13: 11 | R13: 35.5 | T13: TVöD | U13: Anlehner | V13: 45870 | W13: 46142 | X13: 0.06399 | Y13: 5.89 | Z13: 7.34 | AB13: TVöD | AC13: Anwender | AD13: 45870 | AE13: 46142 | AF13: 0.06713 | AG13: 6.18 | AH13: 7.7 | AR13: TVöD | AS13: Anlehner | AT13: 46143 | AV13: 0.06341 | AW13: 5.83 | AX13: 7.27 | BA13: TVöD | BB13: Anwender | BC13: 46143 | BE13: 0.06577 | BF13: 6.05 | BG13: 7.54
A14: Essen | E14: HT Opseo | I14: ZWST | J14: 2 | K14: 12 | R14: 36 | T14: VPD | U14: Anlehner | V14: 01.01.2025 | W14: 31.12.2025 | X14: 0.06077 | Y14: 5.59 | Z14: 6.97 | AB14: VPD | AC14: Anwender | AD14: 01.01.2025 | AE14: 31.12.2025 | AF14: 0.06303 | AG14: 5.8 | AH14: 7.23 | AR14: VPD | AS14: Anlehner | BA14: VPD | BB14: Anwender
A15: Euskirchen | K15: 13 | R15: 36.5
A16: Gelsenkirchen | K16: 14 | R16: 37
A17: Gütersloh | K17: 15 | R17: 37.5
A18: Hagen | R18: 38
A19: Hamm | R19: 38.5
A20: Heinsberg | R20: 39
A21: Herford | R21: 39.5
A22: Herne | R22: 40
A23: Hochsauerlandkreis | R23: 40.5
A24: Höxter | R24: 41
A25: Kleve | R25: 41.5
A26: Köln | R26: 42
A27: Krefeld
A28: Leverkusen
A29: Lippe
A30: Märkischer Kreis
A31: Mettmann
A32: Minden-Lübbecke
A33: Mönchengladbach
A34: Mülheim a. d. Ruhr
A35: Münster
A36: Oberbergischer Kreis
A37: Oberhausen | L37: HT Maternus | M37: HT Opseo
A38: Olpe
A39: Paderborn
A40: Recklinghausen
...

Sheet Anlage 1
A1: Name des Pflegedienstes | E1: IK-Nummer
A2: =Dateneingabe!E4 -> Pflegedienst MORO GmbH | E2: =Dateneingabe!D8 -> 460 502 542
A4: Anlage 1
A5: Nachweis der Kosten / Forderung
A6: ( ausschließlich die Kosten für Stellenanteile, die unter B. ausgewiesene Leistungskomplexe
A7: erwirtschaftet haben; vgl. auch Ziffer C. Personalstruktur )
G8: Nur auszufüllen bei Individualverhandlung
D10: abgeschlossenes Geschäftsjahr | G10: prospektiver Vergütungszeitraum
D12: =YEAR(Dateneingabe!F16) -> 2024 | G12: =YEAR(Dateneingabe!F17) -> 2026
A13: Personalkosten | D13: VK | E13: Kosten | F13: Ø | G13: VK | H13: Kosten | I13: Ø | J13: Veränderung zum abg. Geschäftsjahr
A14: Leitung und Verwaltung Pflegedienst | D14: 0.76 | E14: 36483.94 | F14: =IF(D14<>0,E14/D14,0) -> 48005.184 | I14: =IF(G14 <> 0,H14/G14,0) -> 0 | J14: =IF(OR(I14=0,F14=0),0,I14/F14-1) -> 0
A15: Pflegefachkräfte (staatlich examiniert) excl. Freistellungsanteil PDL | D15: 2.22 | E15: 166043.46 | F15: =IF(D15<>0,E15/D15,0) -> 74794.351 | I15: =IF(G15<>0,H15/G15,0) -> 0 | J15: =IF(OR(I15=0,F15=0),0,I15/F15-1) -> 0
A16: Pflegehilfskräfte (1-jährig) | D16: 0.16 | E16: 8639.71 | F16: =IF(D16<>0,E16/D16,0) -> 53998.187 | I16: =IF(G16<>0,H16/G16,0) -> 0 | J16: =IF(OR(I16=0,F16=0),0,I16/F16-1) -> 0
A17: angelernte Hilfskräfte | D17: 3.63 | E17: 156134.69 | F17: =IF(D17<>0,E17/D17,0) -> 43012.311 | I17: =IF(G17<>0,H17/G17,0) -> 0 | J17: =IF(OR(I17=0,F17=0),0,I17/F17-1) -> 0
A18: Betreuungskräfte | F18: =IF(D18<>0,E18/D18,0) -> 0 | I18: =IF(G18<>0,H18/G18,0) -> 0 | J18: =IF(OR(I18=0,F18=0),0,I18/F18-1) -> 0
A19: BFD und FSJ | F19: =IF(D19<>0,E19/D19,0) -> 0 | I19: =IF(G19<>0,H19/G19,0) -> 0 | J19: =IF(OR(I19=0,F19=0),0,I19/F19-1) -> 0
A20: Summe Personalkosten | D20: =SUM(D14:D19) -> 6.77 | E20: =SUM(E14:E19) -> 367301.8 | F20: =IF(D20<>0,E20/D20,0) -> 54254.328 | G20: =SUM(G14:G19) -> 0 | H20: =SUM(H14:H19) -> 0 | I20: =IF(G20<>0,H20/G20,0) -> 0 | J20: =IF(OR(F20=0,I20=0),0,I20/F20-1) -> 0
A22: Sachkosten | D22: abgeschlossenes Geschäftsjahr | G22: prospektiver Vergütungszeitraum
A23: ( für die unter B. erwirtschafteten Leistungen )
A24: Wirtschaftsbedarf | E24: 947.23 | H24: 0 | J24: =IF(OR(E24=0,H24=0),0,H24/E24-1) -> 0
A25: Verwaltungsbedarf | E25: 26118.5 | J25: =IF(OR(E25=0,H25=0),0,H25/E25-1) -> 0
A26: Fremdleistungen Verwaltung | J26: =IF(OR(E26=0,H26=0),0,H26/E26-1) -> 0
A27: Aufwendungen Fahrzeuge | E27: 13296.2 | J27: =IF(OR(E27=0,H27=0),0,H27/E27-1) -> 0
A28: med. pfleg. Bedarf | E28: 750.27 | J28: =IF(OR(E28=0,H28=0),0,H28/E28-1) -> 0
A29: Fremdleistungen Pflege | J29: =IF(OR(E29=0,H29=0),0,H29/E29-1) -> 0
A30: Verbrauchsgüter | E30: 655.92 | J30: =IF(OR(E30=0,H30=0),0,H30/E30-1) -> 0
A31: Steuern, Abgaben, Versicherungen | E31: 2767.25 | J31: =IF(OR(E31=0,H31=0),0,H31/E31-1) -> 0
A32: Qualitätssicherung | J32: =IF(OR(E32=0,H32=0),0,H32/E32-1) -> 0
A33: Sonstiges (bitte erläutern) | E33: 1144.44 | J33: =IF(OR(E33=0,H33=0),0,H33/E33-1) -> 0
A34: Trägeruml. soweit nicht Fremdlst. Verwaltung | H34: 0 | J34: =IF(OR(E34=0,H34=0),0,H34/E34-1) -> 0
A35: Summe Sachkosten | E35: =SUM(E24:E34) -> 45679.81 | F35: =IF(OR(E35=0,E37=0),0,(E35/(E37))) -> 0.11060979 | H35: =SUM(H24:H34) -> 0 | I35: =IF(OR(H35=0,H37=0),0,(H35/(H37))) -> 0
A37: Summe Personal- und Sachkosten | E37: =E20+E35 -> 412981.61 | H37: =H20+H35 -> 0

Sheet Pflegeassistenz
A1: 1. Ausbildungskosten der Pflegefachassistenzausbildung
B2: =Dateneingabe!E4 -> Pflegedienst MORO GmbH
B4: Auszubildende Pflegefachassistenz
A5: 1. | B5: monatl. Bruttogehalt pro Person in Ausbildung | E5: 1165.69
A6: 2. | B6: `+Jahressonderzahlungen anteilig pro Monat | E6: =E5*0.9/12 -> 87.42675
A7: 3. | B7: `+Sozialversicherungen 25% | D7: =0.25 -> 0.25 | E7: =(E5+E6)*D7 -> 313.27919
B9: `= Summe monatl. Ausbildungskosten | E9: =ROUND(SUM(E5:E7),2) -> 1566.4
N11: Tage | O11: Monate
A12: 2. | B12: Berechnung der anteiligen Monate im folgenden Finanzierungsjahr | I12: Laufzeitbeginn: | K12: =Dateneingabe!E17 -> 46023 | N12: =DATEDIF(K12,K14,"d") -> 364 | O12: =ROUND((N12/30.42),1) -> 12
A14: 2a. | B14: Neu zu berücksichtigende Ausbildungsmonate | I14: Laufzeitende | K14: =Dateneingabe!F17 -> 46387
B16: Namenskürzel Auszubildende | C16: Ausbildungsbeginn | D16: Ausbildungsende | E16: Anzahl Azubildende | G16: Monate | I16: Gesamtmonate | K16: Ausbildungsumfang Teil-/Vollzeit | M16: anteilige Monate
B17: MS | C17: 45444 | D17: 45900 | E17: 1 | F17: =IF(E17="","","x") -> x | G17: 15 | H17: =IF(E17="","","=") -> = | I17: =IF(E17="","",E17*G17) -> 15 | J17: =IF(E17="","","x") -> x | K17: 1 | L17: =IF(E17="","","=") -> = | M17: =IF(E17="","",I17*K17) -> 15
F18: =IF(E18="","","x") | H18: =IF(E18="","","=") | I18: =IF(E18="","",E18*G18) | J18: =IF(E18="","","x") | L18: =IF(E18="","","=") | M18: =IF(E18="","",I18*K18)
F19: =IF(E19="","","x") | H19: =IF(E19="","","=") | I19: =IF(E19="","",E19*G19) | J19: =IF(E19="","","x") | L19: =IF(E19="","","=") | M19: =IF(E19="","",I19*K19)
F20: =IF(E20="","","x") | H20: =IF(E20="","","=") | I20: =IF(E20="","",E20*G20) | J20: =IF(E20="","","x") | L20: =IF(E20="","","=") | M20: =IF(E20="","",I20*K20)
F21: =IF(E21="","","x") | H21: =IF(E21="","","=") | I21: =IF(E21="","",E21*G21) | J21: =IF(E21="","","x") | L21: =IF(E21="","","=") | M21: =IF(E21="","",I21*K21)
F22: =IF(E22="","","x") | H22: =IF(E22="","","=") | I22: =IF(E22="","",E22*G22) | J22: =IF(E22="","","x") | L22: =IF(E22="","","=") | M22: =IF(E22="","",I22*K22)
F23: =IF(E23="","","x") | H23: =IF(E23="","","=") | I23: =IF(E23="","",E23*G23) | J23: =IF(E23="","","x") | L23: =IF(E23="","","=") | M23: =IF(E23="","",I23*K23)
F24: =IF(E24="","","x") | H24: =IF(E24="","","=") | I24: =IF(E24="","",E24*G24) | J24: =IF(E24="","","x") | L24: =IF(E24="","","=") | M24: =IF(E24="","",I24*K24)
F25: =IF(E25="","","x") | H25: =IF(E25="","","=") | I25: =IF(E25="","",E25*G25) | J25: =IF(E25="","","x") | L25: =IF(E25="","","=") | M25: =IF(E25="","",I25*K25)
F26: =IF(E26="","","x") | H26: =IF(E26="","","=") | I26: =IF(E26="","",E26*G26) | J26: =IF(E26="","","x") | L26: =IF(E26="","","=") | M26: =IF(E26="","",I26*K26)
E27: =SUM(E17:E26) -> 1 | K27: Summe anteilige Monate | M27: =SUM(M17:M26) -> 15
A29: 2b. | B29: In der vorherigen Vergütungsvereinbarung berücksichtigte Ausbildungsmonate, die nicht stattfinden konnten (z. B. Ausbildungsabbruch)
B31: Namenskürzel Auszubildende | C31: Folgetag Ausbildungsabbruch | D31: Ende der aktuellen Vergütungsverein-barungslaufzeit | E31: Anzahl Azubildende | G31: Anzahl abzuziehende Monate | I31: Gesamtmonate | K31: Ausbildungsumfang Teil-/Vollzeit | M31: anteilige Monate
F32: =IF(E32="","","x") | H32: =IF(E32="","","=") | I32: =IF(E32="","",E32*G32) | J32: =IF(E32="","","x") | L32: =IF(E32="","","=") | M32: =IF(E32="","",I32*K32*-1)
F33: =IF(E33="","","x") | H33: =IF(E33="","","=") | I33: =IF(E33="","",E33*G33) | J33: =IF(E33="","","x") | L33: =IF(E33="","","=") | M33: =IF(E33="","",I33*K33*-1)
F34: =IF(E34="","","x") | H34: =IF(E34="","","=") | I34: =IF(E34="","",E34*G34) | J34: =IF(E34="","","x") | L34: =IF(E34="","","=") | M34: =IF(E34="","",I34*K34*-1)
F35: =IF(E35="","","x") | H35: =IF(E35="","","=") | I35: =IF(E35="","",E35*G35) | J35: =IF(E35="","","x") | L35: =IF(E35="","","=") | M35: =IF(E35="","",I35*K35*-1)
F36: =IF(E36="","","x") | H36: =IF(E36="","","=") | I36: =IF(E36="","",E36*G36) | J36: =IF(E36="","","x") | L36: =IF(E36="","","=") | M36: =IF(E36="","",I36*K36*-1)
I37: Summe anteilige Monate 2a. + 2b. | M37: =M27+SUM(M32:M36) -> 15
A40: 3. | B40: Berechnung der zu refinanzierenden anteiligen Kosten im folgenden Finanzierungsjahr
C42: monatl. Ausbildungskosten | E42: anteilige Monate | G42: ∑ Punktevolumen | I42: jährlicher Punktwertauf- schlag | K42: Punktwertaufschlag Vereinbarungszeitraum
C43: =E9 -> 1566.4 | D43: =IF(C43=0,"","x") -> x | E43: =M37 -> 15 | F43: =IF(C43=0,"","÷") -> ÷ | G43: =Budgetsteigerung!M47 -> 3348626 | H43: =IF(C43=0,"","=") -> = | I43: =IF(G43=0,"",ROUND(C43*E43/G43,5)) -> 0.00702 | K43: =(C43*E43/(G43/12*O12)) -> 0.0070166092
A46: 4. | B46: Angabe des Punktwertaufschlages für die neue Vergütung zum nächsten 1. Januar
C48: jährlicher Punktwertaufschlag
C49: =I43 -> 0.00702 | D49: =IF(C49>I43,N49,"") | N49: ="Der Punktwertaufschlag in Höhe von "&I43&" Euro darf nicht überschritten werden" -> Der Punktwertaufschlag in Höhe von 0,00702 Euro darf nicht überschritten werden
B51: Der berechnete jährliche Punktwertaufschlag in der Zelle I41 ist der maximal zulässige Punktwertaufschlag für die Vergütungsverhandlung SGB XI.
B52: Als ambulante Pflegeeinrichtung, dürfen Sie diesen unterschreiten. In dem Fall tragen Sie bitte den "gewünschten" Punktwertaufschlag in die Zelle
B53: C49 ein. Bitte beachten Sie, dass dieser Aufschlag maximal fünf Stellen hinter dem Komma haben darf und kleiner oder gleich dem berechneten
B54: jährlichen Punktwertaufschlag in Zelle I41 sein muss. Als Vorschlag wird automatisch der berechnete jährliche Punktwertaufschlag ausgewiesen.

Sheet Betreuungskraft
A1: 1. | B1: Weiterbildungskosten Betreuungskraft
B3: Einsatzstunden p.a. | E3: 1500
B4: Tarifvariante | E4: Tarifanwender | K4: regional übliches Entgelt | L4: 49000
K5: Tarifanlehner | L5: 53000
C6: I. | D6: Lehrgangskosten | I6: 1200 | K6: Tarifanwender | L6: 55000
C8: II. | D8: Personalaufwand
D9: Lehrgangszeit | E9: 120 | G9: =VLOOKUP($E$4,$K$4:$L$6,2) -> 55000 | H9: p.a.
D10: Wegezeiten (10 %) | E10: =E9*0.1 -> 12
D11: Praktikum | E11: =2*39 -> 78
E12: =SUM(E9:E11) -> 210 | G12: =ROUND(G9/$E$3,2) -> 36.67 | I12: =E12*G12 -> 7700.7
I14: =SUM(I6:I12) -> 8900.7
A16: 2. | B16: Jährliche Fortbildungskosten Betreuungskraft
C18: I. | D18: Lehrgangskosten | I18: 300
C20: II. | D20: Personalaufwand
D21: Lehrgangszeit | E21: 12 | G21: =G9 -> 55000 | H21: p.a.
D22: Wegezeiten (10 %) | E22: =E21*0.1 -> 1.2
E23: =SUM(E21:E22) -> 13.2 | G23: =ROUND(G21/$E$3,2) -> 36.67 | I23: =E23*G23 -> 484.044
I25: =SUM(I18:I23) -> 784.044
A27: 3. | B27: Berechnung der Finanzierungsanteile für Weiter- und Fortbildung
A29: 3a | B29: Weiterbildungen Betreuungskräfte
B31: Namenskürzel | I31: Fortbildungskosten
I32: =IF(B32<>"",$I$14,0) -> 0
I33: =IF(B33<>"",$I$14,0) -> 0
I34: =IF(B34<>"",$I$14,0) -> 0
I35: =IF(B35<>"",$I$14,0) -> 0
I36: =IF(B36<>"",$I$14,0) -> 0
I37: =IF(B37<>"",$I$14,0) -> 0
I38: =SUM(I32:I37) -> 0
A40: 3b | B40: Jährliche Fortbildungen Betreuungskräfte
B42: Namenskürzel | I42: Fortbildungskosten
I43: =IF(B43<>"",$I$25,0) -> 0
I44: =IF(B44<>"",$I$25,0) -> 0
I45: =IF(B45<>"",$I$25,0) -> 0
I46: =IF(B46<>"",$I$25,0) -> 0
I47: =IF(B47<>"",$I$25,0) -> 0
I48: =IF(B48<>"",$I$25,0) -> 0
I49: =SUM(I43:I48) -> 0
A51: 4. | B51: Berechnung der zu refinanzierenden anteiligen Kosten im folgenden Finanzierungsjahr
B54: Summe Punktvolumen | I54: =Budgetsteigerung!M47 -> 3348626
B56: Summe Fort- und Weiterbildungskosten | I56: =I38+I49 -> 0
...

Sheet Export
A1: Dateneingabe
A3: =Dateneingabe!A4 -> Pflegedienst MORO GmbH
A4: =Dateneingabe!A5 -> Provinzialstr. 82
A5: =Dateneingabe!A6 -> 44388
A6: =Dateneingabe!C6 -> Dortmund
A8: =Dateneingabe!E4 -> Pflegedienst MORO GmbH
A9: =Dateneingabe!E5 -> Provinzialstr. 82
A10: =Dateneingabe!E6 -> 44388
A11: =Dateneingabe!F6 -> Dortmund
A13: =Dateneingabe!D8 -> 460 502 542
A14: =Dateneingabe!F8 -> Dortmund
A16: =Dateneingabe!C10 -> bpa
A17: Feld wir nicht mehr genutzt
A18: =Dateneingabe!C13 -> Pauschalverhandlung
A20: =Dateneingabe!E16 -> 45292
A21: =Dateneingabe!F16 -> 45657
A22: =Dateneingabe!E17 -> 46023
A23: =Dateneingabe!F17 -> 46387
A25: =Dateneingabe!C20 -> 0.06076
A26: =Dateneingabe!D20 -> 5.59
A27: =Dateneingabe!E20 -> 6.97
A28: =Dateneingabe!C21 -> 0.06289
A29: =Dateneingabe!D21 -> 5.79
A30: =Dateneingabe!E21 -> 7.21
A32: =Dateneingabe!A31 -> 5
A33: =Dateneingabe!C31 -> 40
A34: =Dateneingabe!D31 -> 12
A35: =Dateneingabe!E31 -> 10
A36: =Dateneingabe!F31 -> 3
A38: =Dateneingabe!F35 -> 1223
A39: =Dateneingabe!F36 -> 1363
A40: =Dateneingabe!F37 -> 73
A41: =Dateneingabe!F38 -> 751
A42: =Dateneingabe!F39 -> 0
A43: =Dateneingabe!F40 -> 314
A44: =Dateneingabe!F41 -> 0
A45: =Dateneingabe!F42 -> 0
A46: =Dateneingabe!F43 -> 0
A47: =Dateneingabe!F44 -> 0
A48: =Dateneingabe!F45 -> 116
...

Sheet Datenexport
A1: Name des Trägers | B1: Straße des Trägers | C1: PLZ des Trägers | D1: Ort des Trägers | E1: Name der Einrichtung | F1: Straße der Einrichtung | G1: PLZ der Einrichtung | H1: Ort der Einrichtung | I1: IK | J1: Vergütung von | K1: Vergütung bis | L1: Tarif | M1: Punktwert | N1: LK 15 | O1: LK 15a | P1: Verhandlungsart | Q1: Zuschlag Pflegefachassistenten | R1: Zuschlag MuG
A2: =Dateneingabe!A4 -> Pflegedienst MORO GmbH | B2: =Dateneingabe!A5 -> Provinzialstr. 82 | C2: =Dateneingabe!A6 -> 44388 | D2: =Dateneingabe!C6 -> Dortmund | E2: =Dateneingabe!E4 -> Pflegedienst MORO GmbH | F2: =Dateneingabe!E5 -> Provinzialstr. 82 | G2: =Dateneingabe!E6 -> 44388 | H2: =Dateneingabe!F6 -> Dortmund | I2: =Dateneingabe!D8 -> 460 502 542 | J2: =Dateneingabe!E17 -> 46023 | K2: =Dateneingabe!F17 -> 46387 | L2: =Die_Vergütung_aller_Mitarbeiter_erfolgt_derzeit_nach_dem_Tarif -> regional übliches Entgelt | M2: =Budgetsteigerung!F55 -> 0.06289 | N2: =Budgetsteigerung!F56 -> 5.79 | O2: =Budgetsteigerung!F57 -> 7.21 | P2: =Dateneingabe!C13 -> Pauschalverhandlung | Q2: =Pflegeassistenz!C49 -> 0.00702 | R2: =Betreuungskraft!I64 -> 0
